2020-08-05 09:28:52,553 - kedro_viz.server - ERROR - Exception on /nodes/7366ec9f [GET]
Traceback (most recent call last):
  File "/Users/kiyohito_kunii/anaconda3/envs/viz36/lib/python3.6/site-packages/flask/app.py", line 2447, in wsgi_app
    response = self.full_dispatch_request()
  File "/Users/kiyohito_kunii/anaconda3/envs/viz36/lib/python3.6/site-packages/flask/app.py", line 1952, in full_dispatch_request
    rv = self.handle_user_exception(e)
  File "/Users/kiyohito_kunii/anaconda3/envs/viz36/lib/python3.6/site-packages/flask/app.py", line 1821, in handle_user_exception
    reraise(exc_type, exc_value, tb)
  File "/Users/kiyohito_kunii/anaconda3/envs/viz36/lib/python3.6/site-packages/flask/_compat.py", line 39, in reraise
    raise value
  File "/Users/kiyohito_kunii/anaconda3/envs/viz36/lib/python3.6/site-packages/flask/app.py", line 1950, in full_dispatch_request
    rv = self.dispatch_request()
  File "/Users/kiyohito_kunii/anaconda3/envs/viz36/lib/python3.6/site-packages/flask/app.py", line 1936, in dispatch_request
    return self.view_functions[rule.endpoint](**req.view_args)
  File "/Users/kiyohito_kunii/Desktop/kedro-viz/package/kedro_viz/server.py", line 508, in nodes_metadata
    if node_id == dataset_id and _CATALOG.exists(namespace):
AttributeError: 'DummyCatalog' object has no attribute 'exists'
2020-08-05 09:29:43,668 - kedro_viz.server - ERROR - Exception on /nodes/7366ec9f [GET]
Traceback (most recent call last):
  File "/Users/kiyohito_kunii/anaconda3/envs/viz36/lib/python3.6/site-packages/flask/app.py", line 2447, in wsgi_app
    response = self.full_dispatch_request()
  File "/Users/kiyohito_kunii/anaconda3/envs/viz36/lib/python3.6/site-packages/flask/app.py", line 1952, in full_dispatch_request
    rv = self.handle_user_exception(e)
  File "/Users/kiyohito_kunii/anaconda3/envs/viz36/lib/python3.6/site-packages/flask/app.py", line 1821, in handle_user_exception
    reraise(exc_type, exc_value, tb)
  File "/Users/kiyohito_kunii/anaconda3/envs/viz36/lib/python3.6/site-packages/flask/_compat.py", line 39, in reraise
    raise value
  File "/Users/kiyohito_kunii/anaconda3/envs/viz36/lib/python3.6/site-packages/flask/app.py", line 1950, in full_dispatch_request
    rv = self.dispatch_request()
  File "/Users/kiyohito_kunii/anaconda3/envs/viz36/lib/python3.6/site-packages/flask/app.py", line 1936, in dispatch_request
    return self.view_functions[rule.endpoint](**req.view_args)
  File "/Users/kiyohito_kunii/Desktop/kedro-viz/package/kedro_viz/server.py", line 509, in nodes_metadata
    metadata = _get_dataset_metadata(namespace)
  File "/Users/kiyohito_kunii/Desktop/kedro-viz/package/kedro_viz/server.py", line 522, in _get_dataset_metadata
    dataset = _CATALOG._get_dataset(namespace)  # pylint: disable=protected-access
AttributeError: 'DummyCatalog' object has no attribute '_get_dataset'
2020-08-05 09:30:48,393 - kedro_viz.server - ERROR - Exception on /nodes/7366ec9f [GET]
Traceback (most recent call last):
  File "/Users/kiyohito_kunii/anaconda3/envs/viz36/lib/python3.6/site-packages/flask/app.py", line 2447, in wsgi_app
    response = self.full_dispatch_request()
  File "/Users/kiyohito_kunii/anaconda3/envs/viz36/lib/python3.6/site-packages/flask/app.py", line 1952, in full_dispatch_request
    rv = self.handle_user_exception(e)
  File "/Users/kiyohito_kunii/anaconda3/envs/viz36/lib/python3.6/site-packages/flask/app.py", line 1821, in handle_user_exception
    reraise(exc_type, exc_value, tb)
  File "/Users/kiyohito_kunii/anaconda3/envs/viz36/lib/python3.6/site-packages/flask/_compat.py", line 39, in reraise
    raise value
  File "/Users/kiyohito_kunii/anaconda3/envs/viz36/lib/python3.6/site-packages/flask/app.py", line 1950, in full_dispatch_request
    rv = self.dispatch_request()
  File "/Users/kiyohito_kunii/anaconda3/envs/viz36/lib/python3.6/site-packages/flask/app.py", line 1936, in dispatch_request
    return self.view_functions[rule.endpoint](**req.view_args)
  File "/Users/kiyohito_kunii/Desktop/kedro-viz/package/kedro_viz/server.py", line 509, in nodes_metadata
    metadata = _get_dataset_metadata(namespace)
  File "/Users/kiyohito_kunii/Desktop/kedro-viz/package/kedro_viz/server.py", line 524, in _get_dataset_metadata
    "dataset_type": dataset.__module__,
AttributeError: 'NoneType' object has no attribute '__module__'
2020-08-05 09:44:17,537 - kedro_viz.server - ERROR - Exception on /nodes/7366ec9f [GET]
Traceback (most recent call last):
  File "/Users/kiyohito_kunii/anaconda3/envs/viz36/lib/python3.6/site-packages/flask/app.py", line 2447, in wsgi_app
    response = self.full_dispatch_request()
  File "/Users/kiyohito_kunii/anaconda3/envs/viz36/lib/python3.6/site-packages/flask/app.py", line 1950, in full_dispatch_request
    rv = self.dispatch_request()
  File "/Users/kiyohito_kunii/anaconda3/envs/viz36/lib/python3.6/site-packages/flask/app.py", line 1821, in handle_user_exception
    reraise(exc_type, exc_value, tb)
  File "/Users/kiyohito_kunii/anaconda3/envs/viz36/lib/python3.6/site-packages/flask/_compat.py", line 39, in reraise
    raise value
  File "/Users/kiyohito_kunii/anaconda3/envs/viz36/lib/python3.6/site-packages/flask/app.py", line 1950, in full_dispatch_request
    rv = self.dispatch_request()
  File "/Users/kiyohito_kunii/anaconda3/envs/viz36/lib/python3.6/site-packages/flask/app.py", line 1936, in dispatch_request
    return self.view_functions[rule.endpoint](**req.view_args)
  File "/Users/kiyohito_kunii/Desktop/kedro-viz/package/kedro_viz/server.py", line 509, in nodes_metadata
    metadata = _get_dataset_metadata(namespace)
  File "/Users/kiyohito_kunii/Desktop/kedro-viz/package/kedro_viz/server.py", line 525, in _get_dataset_metadata
    # pylint: disable=protected-access
  File "/Users/kiyohito_kunii/Desktop/kedro-viz/package/kedro_viz/server.py", line 525, in _get_dataset_metadata
    # pylint: disable=protected-access
  File "/Users/kiyohito_kunii/anaconda3/envs/viz36/lib/python3.6/bdb.py", line 51, in trace_dispatch
    return self.dispatch_line(frame)
  File "/Users/kiyohito_kunii/anaconda3/envs/viz36/lib/python3.6/bdb.py", line 69, in dispatch_line
    self.user_line(frame)
  File "/Users/kiyohito_kunii/anaconda3/envs/viz36/lib/python3.6/pdb.py", line 261, in user_line
    self.interaction(frame, None)
  File "/Users/kiyohito_kunii/anaconda3/envs/viz36/lib/python3.6/pdb.py", line 352, in interaction
    self._cmdloop()
  File "/Users/kiyohito_kunii/anaconda3/envs/viz36/lib/python3.6/pdb.py", line 321, in _cmdloop
    self.cmdloop()
  File "/Users/kiyohito_kunii/anaconda3/envs/viz36/lib/python3.6/cmd.py", line 138, in cmdloop
    stop = self.onecmd(line)
  File "/Users/kiyohito_kunii/anaconda3/envs/viz36/lib/python3.6/pdb.py", line 418, in onecmd
    return cmd.Cmd.onecmd(self, line)
  File "/Users/kiyohito_kunii/anaconda3/envs/viz36/lib/python3.6/cmd.py", line 217, in onecmd
    return func(arg)
  File "/Users/kiyohito_kunii/anaconda3/envs/viz36/lib/python3.6/site-packages/_pytest/debugging.py", line 177, in do_quit
    outcomes.exit("Quitting debugger")
  File "/Users/kiyohito_kunii/anaconda3/envs/viz36/lib/python3.6/site-packages/_pytest/outcomes.py", line 75, in exit
    raise Exit(msg, returncode)
_pytest.outcomes.Exit: Quitting debugger
